Workbook
Name Bin_Card_Bal.: 'STOCK CONTROL SHEET'!$F$3:$F$172
Name COMP.STOREPhysicalBal.: 'STOCK CONTROL SHEET'!$I$39:$I$124
Name COMP.STOREPRIMARY: 'STOCK CONTROL SHEET'!$B$39:$N$124
Name COMP.STOREReorderLevels: 'STOCK CONTROL SHEET'!$M$39:$M$124
Name COMPMaterialNo: 'STOCK CONTROL SHEET'!$B$39:$B$124
Name Details: 'STOCK CONTROL SHEET'!$B$4:$D$172
Name Details: 'STOCK CONTROL SHEET'!$B$4:$D$172,'STOCK CONTROL SHEET'!$I$4:$I$172
Name INOUTCODE: 'COMPUTER STORE'!$D$3:$D$11
Name INOUTCODE: MAINTENANCE!$D$3:$D$11
Name INOUTCODE: 'SF STORE'!$D$3:$D$123
Name INOUTQTY: 'COMPUTER STORE'!$G$3:$G$11
Name INOUTQTY: MAINTENANCE!$G$3:$G$11
Name INOUTQTY: 'SF STORE'!$G$3:$G$123
Name ItemDescription: 'STOCK CONTROL SHEET'!$C$4:$C$172
Name MAINT.STOREPhysicalStockBal.: 'STOCK CONTROL SHEET'!$I$125:$I$172
Name MAINT.STOREPRIMARY: 'STOCK CONTROL SHEET'!$B$125:$N$172
Name MAINT.STOREReorderLevels: 'STOCK CONTROL SHEET'!$M$125:$M$172
Name MAINTMaterialNo: 'STOCK CONTROL SHEET'!$B$125:$B$172
Name NativeTimeline_Date: #N/A
Name NativeTimeline_Date1: #N/A
Name NativeTimeline_Date2: #N/A
Name NativeTimeline_Date3: #N/A
Name Opening_S5_Bin_Card_Bal.: 'STOCK CONTROL SHEET'!$E$4:$E$172
Name Physical_Stock_Bal.: SF.STOREPRIMARY[Physical Stock Bal.]
Name Qty._Deficit: SF.STOREPRIMARY[Qty. Deficit]
Name Qty._Surplus: 'STOCK CONTROL SHEET'!$K:$K
Name Reorder_Levels: 'STOCK CONTROL SHEET'!$M:$M
Name ROLL: SF.STOREPRIMARY[Unit of Issue]
Name Running_Balance: 'COMPUTER STORE'!$J:$J
Name Running_Balance: MAINTENANCE!$J:$J
Name Running_Balance: 'SF STORE'!$J:$J
Name SF.STORE.TABLE: SF.STOREPRIMARY[]
Name SFMaterialNo: SF.STOREPRIMARY[Material No]
Name Slicer_Department: #N/A
Name Slicer_Department1: #N/A
Name Slicer_Department2: #N/A
Name Slicer_Department3: #N/A
Name Slicer_In_Out_Qty: #N/A
Name Slicer_In_Out_Qty1: #N/A
Name Slicer_In_Out_Qty2: #N/A
Name Slicer_In_Out_Qty3: #N/A
Name Slicer_Item_Description: #N/A
Name Slicer_Item_Description1: #N/A
Name Slicer_Item_Description2: #N/A
Name Slicer_Item_Description3: #N/A
Name Slicer_Store: #N/A
Name Slicer_Type: #N/A
Name Slicer_Type1: #N/A
Name Slicer_Type2: #N/A
Name Slicer_Type3: #N/A
Name Slicer_Value_of_Deficiency: #N/A
Name Slicer_Value_of_Surplus: #N/A
Name TransactionType: 'COMPUTER STORE'!$M$4:$M$6
Name TransactionType: MAINTENANCE!$M$4:$M$6
Name TransactionType: 'SF STORE'!$M$4:$M$6
Name Type: UnitsTable[Type]
Name Type: ComputerStoreUnitsTable[Type]
Name Type: MAINTENANCEUnitsTable[Type]
Name Type: UnitsTable[Type]
Name Type: UnitsTable[Type]

Sheet STOCK CONTROL SHEET
A1: STORE | B1: STOCK CONTROL SHEET FOR STATIONERY|SF|COMPUTER & MAINTENANCE STORE
B2: PRIMARY STOCK CONTROL DATA FOR THREE STORES
A3: SF STORE | B3: Material No | C3: Item Description | D3: Unit of Issue | E3: Opening S5 Bin Card Bal. | F3: In&Out Qty | G3: Bin Card Balance | H3: Opening Physical Stock Count. | I3: Physical Stock Bal. | J3: Qty. Deficit | K3: Qty. Surplus | L3: Reorder Quantity | M3: Reorder Levels | N3: Remarks
B4: 282014 | C4: Tissue Papers | D4: ROLL | F4: =SUMIF(UnitsTable[Item Description],'STOCK CONTROL SHEET'!C4,UnitsTable[Running Balance]) -> 0 | G4: =IF(SUM(E4,F4)<0,"",SUM(E4,F4)) -> 0 | I4: =IF(SUM(H4,F4)<0,"",SUM(H4,F4)) -> 0 | J4: =IF(G4-I4<=0,"",G4-I4) | K4: =IF(I4-G4<=0,"",I4-G4) | L4: 12720 | M4: 500 | N4: =IF(I4<=M4,"Reorder","Available") -> Reorder
B5: 100126 | C5: Administration Folders | D5: PCS | E5: 375 | F5: =SUMIF(UnitsTable[Item Description],'STOCK CONTROL SHEET'!C5,UnitsTable[Running Balance]) -> 0 | G5: =IF(SUM(E5,F5)<0,"",SUM(E5,F5)) -> 375 | H5: 0 | I5: =IF(SUM(H5,F5)<0,"",SUM(H5,F5)) -> 0 | J5: =IF(G5-I5<=0,"",G5-I5) -> 375 | K5: =IF(I5-G5<=0,"",I5-G5) | L5: 1800 | M5: 450 | N5: =IF(I5<=M5,"Reorder","Available") -> Reorder
B6: 100128 | C6: Age Benefit Folders | D6: PCS | E6: 100 | F6: =SUMIF(UnitsTable[Item Description],'STOCK CONTROL SHEET'!C6,UnitsTable[Running Balance]) -> 0 | G6: =IF(SUM(E6,F6)<0,"",SUM(E6,F6)) -> 100 | H6: 176 | I6: =IF(SUM(H6,F6)<0,"",SUM(H6,F6)) -> 176 | J6: =IF(G6-I6<=0,"",G6-I6) | K6: =IF(I6-G6<=0,"",I6-G6) -> 76 | L6: 20000 | M6: 4500 | N6: =IF(I6<=M6,"Reorder","Available") -> Reorder
B7: 100216 | C7: App. For Personal Exemption Forms | D7: PCS | F7: =SUMIF(UnitsTable[Item Description],'STOCK CONTROL SHEET'!C7,UnitsTable[Running Balance]) -> 0 | G7: =IF(SUM(E7,F7)<0,"",SUM(E7,F7)) -> 0 | I7: =IF(SUM(H7,F7)<0,"",SUM(H7,F7)) -> 0 | J7: =IF(G7-I7<=0,"",G7-I7) | K7: =IF(I7-G7<=0,"",I7-G7) | M7: 3000 | N7: =IF(I7<=M7,"Reorder","Available") -> Reorder
B8: 100139 | C8: App. For Employer SF/001 | D8: PCS | E8: 12750 | F8: =SUMIF(UnitsTable[Item Description],'STOCK CONTROL SHEET'!C8,UnitsTable[Running Balance]) -> -4000 | G8: =IF(SUM(E8,F8)<0,"",SUM(E8,F8)) -> 8750 | H8: 10000 | I8: =IF(SUM(H8,F8)<0,"",SUM(H8,F8)) -> 6000 | J8: =IF(G8-I8<=0,"",G8-I8) -> 2750 | K8: =IF(I8-G8<=0,"",I8-G8) | L8: 60000 | M8: 15000 | N8: =IF(I8<=M8,"Reorder","Available") -> Reorder
B9: 100218 | C9: Ben. App. Forms SF/001 | D9: PCS | E9: 14800 | F9: =SUMIF(UnitsTable[Item Description],'STOCK CONTROL SHEET'!C9,UnitsTable[Running Balance]) -> -5850 | G9: =IF(SUM(E9,F9)<0,"",SUM(E9,F9)) -> 8950 | H9: 11000 | I9: =IF(SUM(H9,F9)<0,"",SUM(H9,F9)) -> 5150 | J9: =IF(G9-I9<=0,"",G9-I9) -> 3800 | K9: =IF(I9-G9<=0,"",I9-G9) | L9: 30000 | M9: 7500 | N9: =IF(I9<=M9,"Reorder","Available") -> Reorder
B10: 100220 | C10: Payment of Benefit Forms/004 | D10: PCS | E10: 35 | F10: =SUMIF(UnitsTable[Item Description],'STOCK CONTROL SHEET'!C10,UnitsTable[Running Balance]) -> -5300 | G10: =IF(SUM(E10,F10)<0,"",SUM(E10,F10)) | H10: 29 | I10: =IF(SUM(H10,F10)<0,"",SUM(H10,F10)) | J10: =IF(G10-I10<=0,"",G10-I10) -> #VALUE! | K10: =IF(I10-G10<=0,"",I10-G10) -> #VALUE! | L10: 30000 | M10: 7500 | N10: =IF(I10<=M10,"Reorder","Available") -> Available
B11: 100210 | C11: Claim Confirmation SF/D/005 | D11: PCS | F11: =SUMIF(UnitsTable[Item Description],'STOCK CONTROL SHEET'!C11,UnitsTable[Running Balance]) -> 0 | G11: =IF(SUM(E11,F11)<0,"",SUM(E11,F11)) -> 0 | I11: =IF(SUM(H11,F11)<0,"",SUM(H11,F11)) -> 0 | J11: =IF(G11-I11<=0,"",G11-I11) | K11: =IF(I11-G11<=0,"",I11-G11) | L11: 30000 | M11: 7500 | N11: =IF(I11<=M11,"Reorder","Available") -> Reorder
B12: 100162 | C12: Confidential Folders Pink | D12: PCS | E12: 170 | F12: =SUMIF(UnitsTable[Item Description],'STOCK CONTROL SHEET'!C12,UnitsTable[Running Balance]) -> 0 | G12: =IF(SUM(E12,F12)<0,"",SUM(E12,F12)) -> 170 | H12: 5 | I12: =IF(SUM(H12,F12)<0,"",SUM(H12,F12)) -> 5 | J12: =IF(G12-I12<=0,"",G12-I12) -> 165 | K12: =IF(I12-G12<=0,"",I12-G12) | L12: 1000 | M12: 250 | N12: =IF(I12<=M12,"Reorder","Available") -> Reorder
B13: 100144 | C13: Dummy B Certificate | D13: PCS | E13: 201 | F13: =SUMIF(UnitsTable[Item Description],'STOCK CONTROL SHEET'!C13,UnitsTable[Running Balance]) -> 0 | G13: =IF(SUM(E13,F13)<0,"",SUM(E13,F13)) -> 201 | H13: 201 | I13: =IF(SUM(H13,F13)<0,"",SUM(H13,F13)) -> 201 | J13: =IF(G13-I13<=0,"",G13-I13) | K13: =IF(I13-G13<=0,"",I13-G13) | L13: 300 | M13: 100 | N13: =IF(I13<=M13,"Reorder","Available") -> Available
B14: 100125 | C14: Empty Cartons | D14: NO | E14: 497 | F14: =SUMIF(UnitsTable[Item Description],'STOCK CONTROL SHEET'!C14,UnitsTable[Running Balance]) -> 0 | G14: =IF(SUM(E14,F14)<0,"",SUM(E14,F14)) -> 497 | H14: 367 | I14: =IF(SUM(H14,F14)<0,"",SUM(H14,F14)) -> 367 | J14: =IF(G14-I14<=0,"",G14-I14) -> 130 | K14: =IF(I14-G14<=0,"",I14-G14) | L14: 200 | M14: 100 | N14: =IF(I14<=M14,"Reorder","Available") -> Available
B15: 100123 | C15: Envelopes A4 | D15: PCS | E15: 12045 | F15: =SUMIF(UnitsTable[Item Description],'STOCK CONTROL SHEET'!C15,UnitsTable[Running Balance]) -> -2400 | G15: =IF(SUM(E15,F15)<0,"",SUM(E15,F15)) -> 9645 | H15: 15251 | I15: =IF(SUM(H15,F15)<0,"",SUM(H15,F15)) -> 12851 | J15: =IF(G15-I15<=0,"",G15-I15) | K15: =IF(I15-G15<=0,"",I15-G15) -> 3206 | L15: 40000 | M15: 9000 | N15: =IF(I15<=M15,"Reorder","Available") -> Available
B16: 100228 | C16: A3 Security Envelopes | D16: PCS | E16: 10 | F16: =SUMIF(UnitsTable[Item Description],'STOCK CONTROL SHEET'!C16,UnitsTable[Running Balance]) -> 0 | G16: =IF(SUM(E16,F16)<0,"",SUM(E16,F16)) -> 10 | H16: 0 | I16: =IF(SUM(H16,F16)<0,"",SUM(H16,F16)) -> 0 | J16: =IF(G16-I16<=0,"",G16-I16) -> 10 | K16: =IF(I16-G16<=0,"",I16-G16) | L16: 1600 | M16: 600 | N16: =IF(I16<=M16,"Reorder","Available") -> Reorder
B17: 100124 | C17: Envelopes A3 (16*12) White | D17: PCS | E17: 1336 | F17: =SUMIF(UnitsTable[Item Description],'STOCK CONTROL SHEET'!C17,UnitsTable[Running Balance]) -> -250 | G17: =IF(SUM(E17,F17)<0,"",SUM(E17,F17)) -> 1086 | H17: 1361 | I17: =IF(SUM(H17,F17)<0,"",SUM(H17,F17)) -> 1111 | J17: =IF(G17-I17<=0,"",G17-I17) | K17: =IF(I17-G17<=0,"",I17-G17) -> 25 | L17: 2000 | M17: 450 | N17: =IF(I17<=M17,"Reorder","Available") -> Available
B18: 100122 | C18: Envelopes A5 | D18: PCS | E18: 14646 | F18: =SUMIF(UnitsTable[Item Description],'STOCK CONTROL SHEET'!C18,UnitsTable[Running Balance]) -> -1910 | G18: =IF(SUM(E18,F18)<0,"",SUM(E18,F18)) -> 12736 | H18: 11067 | I18: =IF(SUM(H18,F18)<0,"",SUM(H18,F18)) -> 9157 | J18: =IF(G18-I18<=0,"",G18-I18) -> 3579 | K18: =IF(I18-G18<=0,"",I18-G18) | L18: 15000 | M18: 3750 | N18: =IF(I18<=M18,"Reorder","Available") -> Available
B19: 100130 | C19: Emigration Benefit Folders | D19: PCS | E19: 2210 | F19: =SUMIF(UnitsTable[Item Description],'STOCK CONTROL SHEET'!C19,UnitsTable[Running Balance]) -> -120 | G19: =IF(SUM(E19,F19)<0,"",SUM(E19,F19)) -> 2090 | H19: 2498 | I19: =IF(SUM(H19,F19)<0,"",SUM(H19,F19)) -> 2378 | J19: =IF(G19-I19<=0,"",G19-I19) | K19: =IF(I19-G19<=0,"",I19-G19) -> 288 | L19: 270 | M19: 68 | N19: =IF(I19<=M19,"Reorder","Available") -> Available
B20: 100138 | C20: Fingerprint Forms SF/003 | D20: PCS | E20: 31 | F20: =SUMIF(UnitsTable[Item Description],'STOCK CONTROL SHEET'!C20,UnitsTable[Running Balance]) -> -4000 | G20: =IF(SUM(E20,F20)<0,"",SUM(E20,F20)) | H20: 9 | I20: =IF(SUM(H20,F20)<0,"",SUM(H20,F20)) | J20: =IF(G20-I20<=0,"",G20-I20) -> #VALUE! | K20: =IF(I20-G20<=0,"",I20-G20) -> #VALUE! | L20: 90000 | M20: 22500 | N20: =IF(I20<=M20,"Reorder","Available") -> Available
B21: 100221 | C21: Funeral Grant Forms 006 | D21: PCS | E21: 445 | F21: =SUMIF(UnitsTable[Item Description],'STOCK CONTROL SHEET'!C21,UnitsTable[Running Balance]) -> -180 | G21: =IF(SUM(E21,F21)<0,"",SUM(E21,F21)) -> 265 | H21: 222 | I21: =IF(SUM(H21,F21)<0,"",SUM(H21,F21)) -> 42 | J21: =IF(G21-I21<=0,"",G21-I21) -> 223 | K21: =IF(I21-G21<=0,"",I21-G21) | L21: 5000 | M21: 1250 | N21: =IF(I21<=M21,"Reorder","Available") -> Reorder
B22: 100155 | C22: Finance Account Folders | D22: PCS | E22: 104 | F22: =SUMIF(UnitsTable[Item Description],'STOCK CONTROL SHEET'!C22,UnitsTable[Running Balance]) -> -60 | G22: =IF(SUM(E22,F22)<0,"",SUM(E22,F22)) -> 44 | H22: 62 | I22: =IF(SUM(H22,F22)<0,"",SUM(H22,F22)) -> 2 | J22: =IF(G22-I22<=0,"",G22-I22) -> 42 | K22: =IF(I22-G22<=0,"",I22-G22) | L22: 500 | M22: 125 | N22: =IF(I22<=M22,"Reorder","Available") -> Reorder
B23: 100219 | C23: Invalidity Ben. Forms/002 | D23: PCS | E23: 33218 | F23: =SUMIF(UnitsTable[Item Description],'STOCK CONTROL SHEET'!C23,UnitsTable[Running Balance]) -> 0 | G23: =IF(SUM(E23,F23)<0,"",SUM(E23,F23)) -> 33218 | H23: 9100 | I23: =IF(SUM(H23,F23)<0,"",SUM(H23,F23)) -> 9100 | J23: =IF(G23-I23<=0,"",G23-I23) -> 24118 | K23: =IF(I23-G23<=0,"",I23-G23) | L23: 3000 | M23: 1500 | N23: =IF(I23<=M23,"Reorder","Available") -> Available
... B26: 100145 | C26: Membership Cards (Blank) | D26: PCS | E26: 473900 | F26: =SUMIF(UnitsTable[Item Description],'STOCK CONTROL SHEET'!C26,UnitsTable[Running Balance]) -> -43000 | G26: =IF(SUM(E26,F26)<0,"",SUM(E26,F26)) -> 430900 | H26: 512500 | I26: =IF(SUM(H26,F26)<0,"",SUM(H26,F26)) -> 469500 | J26: =IF(G26-I26<=0,"",G26-I26) | K26: =IF(I26-G26<=0,"",I26-G26) -> 38600 | L26: 600000 | M26: 154000 | N26: =IF(I26<=M26,"Reorder","Available") -> Available
B27: 100205 | C27: Employee Registration 003 | D27: PCS | E27: 5 | F27: =SUMIF(UnitsTable[Item Description],'STOCK CONTROL SHEET'!C27,UnitsTable[Running Balance]) -> 0 | G27: =IF(SUM(E27,F27)<0,"",SUM(E27,F27)) -> 5 | H27: 5 | I27: =IF(SUM(H27,F27)<0,"",SUM(H27,F27)) -> 5 | J27: =IF(G27-I27<=0,"",G27-I27) | K27: =IF(I27-G27<=0,"",I27-G27) | N27: =IF(I27<=M27,"Reorder","Available") -> Available
B28: 100164 | C28: Verification of Claim SF 87 | D28: PCS | E28: 36340 | F28: =SUMIF(UnitsTable[Item Description],'STOCK CONTROL SHEET'!C28,UnitsTable[Running Balance]) -> 0 | G28: =IF(SUM(E28,F28)<0,"",SUM(E28,F28)) -> 36340 | H28: 36340 | I28: =IF(SUM(H28,F28)<0,"",SUM(H28,F28)) -> 36340 | J28: =IF(G28-I28<=0,"",G28-I28) | K28: =IF(I28-G28<=0,"",I28-G28) | L28: 30000 | M28: 3000 | N28: =IF(I28<=M28,"Reorder","Available") -> Available
B29: 100211 | C29: Survivor Ben. Form | D29: PCS | E29: 4910 | F29: =SUMIF(UnitsTable[Item Description],'STOCK CONTROL SHEET'!C29,UnitsTable[Running Balance]) -> -1400 | G29: =IF(SUM(E29,F29)<0,"",SUM(E29,F29)) -> 3510 | H29: 4900 | I29: =IF(SUM(H29,F29)<0,"",SUM(H29,F29)) -> 3500 | J29: =IF(G29-I29<=0,"",G29-I29) -> 10 | K29: =IF(I29-G29<=0,"",I29-G29) | M29: 1500 | N29: =IF(I29<=M29,"Reorder","Available") -> Available
B30: 100222 | C30: Unsound Mind DF/007 | D30: PCS | F30: =SUMIF(UnitsTable[Item Description],'STOCK CONTROL SHEET'!C30,UnitsTable[Running Balance]) -> 0 | G30: =IF(SUM(E30,F30)<0,"",SUM(E30,F30)) -> 0 | I30: =IF(SUM(H30,F30)<0,"",SUM(H30,F30)) -> 0 | J30: =IF(G30-I30<=0,"",G30-I30) | K30: =IF(I30-G30<=0,"",I30-G30) | N30: =IF(I30<=M30,"Reorder","Available") -> Reorder
B31: 26 | C31: Plastic Bags A4 | D31: PCS | E31: 20 | F31: =SUMIF(UnitsTable[Item Description],'STOCK CONTROL SHEET'!C31,UnitsTable[Running Balance]) -> 0 | G31: =IF(SUM(E31,F31)<0,"",SUM(E31,F31)) -> 20 | H31: 68 | I31: =IF(SUM(H31,F31)<0,"",SUM(H31,F31)) -> 68 | J31: =IF(G31-I31<=0,"",G31-I31) | K31: =IF(I31-G31<=0,"",I31-G31) -> 48 | N31: =IF(I31<=M31,"Reorder","Available") -> Available
B32: 27 | C32: Plastic Bags A3 | D32: PCS | E32: 0 | F32: =SUMIF(UnitsTable[Item Description],'STOCK CONTROL SHEET'!C32,UnitsTable[Running Balance]) -> 0 | G32: =IF(SUM(E32,F32)<0,"",SUM(E32,F32)) -> 0 | H32: 1500 | I32: =IF(SUM(H32,F32)<0,"",SUM(H32,F32)) -> 1500 | J32: =IF(G32-I32<=0,"",G32-I32) | K32: =IF(I32-G32<=0,"",I32-G32) -> 1500 | N32: =IF(I32<=M32,"Reorder","Available") -> Available
B33: 100181 | C33: Registration Gen. Folders | D33: PCS | E33: 26065 | F33: =SUMIF(UnitsTable[Item Description],'STOCK CONTROL SHEET'!C33,UnitsTable[Running Balance]) -> -2700 | G33: =IF(SUM(E33,F33)<0,"",SUM(E33,F33)) -> 23365 | H33: 23400 | I33: =IF(SUM(H33,F33)<0,"",SUM(H33,F33)) -> 20700 | J33: =IF(G33-I33<=0,"",G33-I33) -> 2665 | K33: =IF(I33-G33<=0,"",I33-G33) | L33: 400000 | M33: 9000 | N33: =IF(I33<=M33,"Reorder","Available") -> Available
B34: 100213 | C34: Schedule of Contribution | D34: PCS | E34: 33298 | F34: =SUMIF(UnitsTable[Item Description],'STOCK CONTROL SHEET'!C34,UnitsTable[Running Balance]) -> -1000 | G34: =IF(SUM(E34,F34)<0,"",SUM(E34,F34)) -> 32298 | H34: 33298 | I34: =IF(SUM(H34,F34)<0,"",SUM(H34,F34)) -> 32298 | J34: =IF(G34-I34<=0,"",G34-I34) | K34: =IF(I34-G34<=0,"",I34-G34) | L34: 50000 | M34: 12500 | N34: =IF(I34<=M34,"Reorder","Available") -> Available
B35: 100177 | C35: Survivor Benefit Folders | D35: PCS | E35: 425 | F35: =SUMIF(UnitsTable[Item Description],'STOCK CONTROL SHEET'!C35,UnitsTable[Running Balance]) -> 0 | G35: =IF(SUM(E35,F35)<0,"",SUM(E35,F35)) -> 425 | H35: 679 | I35: =IF(SUM(H35,F35)<0,"",SUM(H35,F35)) -> 679 | J35: =IF(G35-I35<=0,"",G35-I35) | K35: =IF(I35-G35<=0,"",I35-G35) -> 254 | M35: 1250 | N35: =IF(I35<=M35,"Reorder","Available") -> Reorder
B36: 100159 | C36: Union Medical Cover Folders | D36: PCS | E36: 0 | F36: =SUMIF(UnitsTable[Item Description],'STOCK CONTROL SHEET'!C36,UnitsTable[Running Balance]) -> 0 | G36: =IF(SUM(E36,F36)<0,"",SUM(E36,F36)) -> 0 | H36: 159 | I36: =IF(SUM(H36,F36)<0,"",SUM(H36,F36)) -> 159 | J36: =IF(G36-I36<=0,"",G36-I36) | K36: =IF(I36-G36<=0,"",I36-G36) -> 159 | N36: =IF(I36<=M36,"Reorder","Available") -> Available
B37: 100150 | C37: SF/219 Forms | D37: PCS | E37: 4225 | F37: =SUMIF(UnitsTable[Item Description],'STOCK CONTROL SHEET'!C37,UnitsTable[Running Balance]) -> 0 | G37: =IF(SUM(E37,F37)<0,"",SUM(E37,F37)) -> 4225 | H37: 4225 | I37: =IF(SUM(H37,F37)<0,"",SUM(H37,F37)) -> 4225 | J37: =IF(G37-I37<=0,"",G37-I37) | K37: =IF(I37-G37<=0,"",I37-G37) | N37: =IF(I37<=M37,"Reorder","Available") -> Available
B38: 100127 | C38: Withdrawal Ben. Folders | D38: PCS | E38: 1140 | F38: =SUMIF(UnitsTable[Item Description],'STOCK CONTROL SHEET'!C38,UnitsTable[Running Balance]) -> 0 | G38: =IF(SUM(E38,F38)<0,"",SUM(E38,F38)) -> 1140 | H38: 750 | I38: =IF(SUM(H38,F38)<0,"",SUM(H38,F38)) -> 750 | J38: =IF(G38-I38<=0,"",G38-I38) -> 390 | K38: =IF(I38-G38<=0,"",I38-G38) | L38: 15000 | M38: 5000 | N38: =IF(I38<=M38,"Reorder","Available") -> Reorder
A39: COMPUTER STORE | B39: 100172 | C39: 1 Part Statement Paper | D39: PCS | E39: 82000 | F39: =SUMIF(ComputerStoreUnitsTable[Item Description],'STOCK CONTROL SHEET'!C39,ComputerStoreUnitsTable[Running Balance]) -> -1000 | G39: =IF(SUM(E39,F39)<0,"",SUM(E39,F39)) -> 81000 | H39: 236000 | I39: =IF(SUM(H39,F39)<0,"",SUM(H39,F39)) -> 235000 | J39: =IF(G39-I39<=0,"",G39-I39) | K39: =IF(I39-G39<=0,"",I39-G39) -> 154000 | L39: 400000 | M39: 150000 | N39: =IF(I39<=M39,"Reorder","Available") -> Available
B40: 41 | C40: Tonner Kit TK-8525 (Magenta) | D40: NO | F40: =SUMIF(ComputerStoreUnitsTable[Item Description],'STOCK CONTROL SHEET'!C40,ComputerStoreUnitsTable[Running Balance]) -> 0 | G40: =IF(SUM(E40,F40)<0,"",SUM(E40,F40)) -> 0 | I40: =IF(SUM(H40,F40)<0,"",SUM(H40,F40)) -> 0 | J40: =IF(G40-I40<=0,"",G40-I40) | K40: =IF(I40-G40<=0,"",I40-G40) | N40: =IF(I40<=M40,"Reorder","Available") -> Reorder
C41: Tonner Laserjet CF350A Black | D41: NO | F41: =SUMIF(ComputerStoreUnitsTable[Item Description],'STOCK CONTROL SHEET'!C41,ComputerStoreUnitsTable[Running Balance]) -> 0 | G41: =SUM(E41,F41) -> 0 | H41: 3 | I41: =IF(SUM(H41,F41)<0,"",SUM(H41,F41)) -> 3 | J41: =IF(G41-I41<=0,"",G41-I41) | K41: =IF(I41-G41<=0,"",I41-G41) -> 3 | N41: =IF(I41<=M41,"Reorder","Available") -> Available
C42: Tonner Laserjet CF350A Yellow | D42: NO | F42: =SUMIF(ComputerStoreUnitsTable[Item Description],'STOCK CONTROL SHEET'!C42,ComputerStoreUnitsTable[Running Balance]) -> 0 | G42: =SUM(E42,F42) -> 0 | H42: 1 | I42: =IF(SUM(H42,F42)<0,"",SUM(H42,F42)) -> 1 | J42: =IF(G42-I42<=0,"",G42-I42) | K42: =IF(I42-G42<=0,"",I42-G42) -> 1 | N42: =IF(I42<=M42,"Reorder","Available") -> Available
...

Sheet INVENTORY STATUS
A1: LIVE TRACKING UPDATE OF STOCK STATUS PER STORE
A2: Current Inventory | F2: STORE | G2: Inventory Status
A3: Material No | B3: Item Description | C3: Unit Of Issue | D3: Reorder Levels | E3: Quantity | G3: Material No | H3: In Stock | I3: Out of Stock
A4: =SFMaterialNo -> 282014 | B4: =IF(A4="","",VLOOKUP(A4,SF.STOREPRIMARY[],2,FALSE)) -> Tissue Papers | C4: =IF(A4="","",VLOOKUP(A4,'STOCK CONTROL SHEET'!Details,3,FALSE)) -> ROLL | D4: =SF.STOREPRIMARY[Reorder Levels] -> 500 | E4: =SF.STOREPRIMARY[Physical Stock Bal.] -> 0 | F4: SF STORE | G4: =SFMaterialNo -> 282014 | H4: =IF(Table2[[#This Row],[Quantity]]>Table2[[#This Row],[Reorder Levels]],Table2[Item Description],"") | I4: =IF(Table2[[#This Row],[Quantity]]<=Table2[[#This Row],[Reorder Levels]],Table2[Item Description],"") -> Tissue Papers
A5: =SFMaterialNo -> 100126 | B5: =IF(A5="","",VLOOKUP(A5,SF.STOREPRIMARY[],2,FALSE)) -> Administration Folders | C5: =IF(A5="","",VLOOKUP(A5,'STOCK CONTROL SHEET'!Details,3,FALSE)) -> PCS | D5: =SF.STOREPRIMARY[Reorder Levels] -> 450 | E5: =SF.STOREPRIMARY[Physical Stock Bal.] -> 0 | G5: =SFMaterialNo -> 100126 | H5: =IF(Table2[[#This Row],[Quantity]]>Table2[[#This Row],[Reorder Levels]],Table2[Item Description],"") | I5: =IF(Table2[[#This Row],[Quantity]]<=Table2[[#This Row],[Reorder Levels]],Table2[Item Description],"") -> Administration Folders
A6: =SFMaterialNo -> 100128 | B6: =IF(A6="","",VLOOKUP(A6,SF.STOREPRIMARY[],2,FALSE)) -> Age Benefit Folders | C6: =IF(A6="","",VLOOKUP(A6,'STOCK CONTROL SHEET'!Details,3,FALSE)) -> PCS | D6: =SF.STOREPRIMARY[Reorder Levels] -> 4500 | E6: =SF.STOREPRIMARY[Physical Stock Bal.] -> 176 | G6: =SFMaterialNo -> 100128 | H6: =IF(Table2[[#This Row],[Quantity]]>Table2[[#This Row],[Reorder Levels]],Table2[Item Description],"") | I6: =IF(Table2[[#This Row],[Quantity]]<=Table2[[#This Row],[Reorder Levels]],Table2[Item Description],"") -> Age Benefit Folders
A7: =SFMaterialNo -> 100216 | B7: =IF(A7="","",VLOOKUP(A7,SF.STOREPRIMARY[],2,FALSE)) -> App. For Personal Exemption Forms | C7: =IF(A7="","",VLOOKUP(A7,'STOCK CONTROL SHEET'!Details,3,FALSE)) -> PCS | D7: =SF.STOREPRIMARY[Reorder Levels] -> 3000 | E7: =SF.STOREPRIMARY[Physical Stock Bal.] -> 0 | G7: =SFMaterialNo -> 100216 | H7: =IF(Table2[[#This Row],[Quantity]]>Table2[[#This Row],[Reorder Levels]],Table2[Item Description],"") | I7: =IF(Table2[[#This Row],[Quantity]]<=Table2[[#This Row],[Reorder Levels]],Table2[Item Description],"") -> App. For Personal Exemption Forms
A8: =SFMaterialNo -> 100139 | B8: =IF(A8="","",VLOOKUP(A8,SF.STOREPRIMARY[],2,FALSE)) -> App. For Employer SF/001 | C8: =IF(A8="","",VLOOKUP(A8,'STOCK CONTROL SHEET'!Details,3,FALSE)) -> PCS | D8: =SF.STOREPRIMARY[Reorder Levels] -> 15000 | E8: =SF.STOREPRIMARY[Physical Stock Bal.] -> 6000 | G8: =SFMaterialNo -> 100139 | H8: =IF(Table2[[#This Row],[Quantity]]>Table2[[#This Row],[Reorder Levels]],Table2[Item Description],"") | I8: =IF(Table2[[#This Row],[Quantity]]<=Table2[[#This Row],[Reorder Levels]],Table2[Item Description],"") -> App. For Employer SF/001
A9: =SFMaterialNo -> 100218 | B9: =IF(A9="","",VLOOKUP(A9,SF.STOREPRIMARY[],2,FALSE)) -> Ben. App. Forms SF/001 | C9: =IF(A9="","",VLOOKUP(A9,'STOCK CONTROL SHEET'!Details,3,FALSE)) -> PCS | D9: =SF.STOREPRIMARY[Reorder Levels] -> 7500 | E9: =SF.STOREPRIMARY[Physical Stock Bal.] -> 5150 | G9: =SFMaterialNo -> 100218 | H9: =IF(Table2[[#This Row],[Quantity]]>Table2[[#This Row],[Reorder Levels]],Table2[Item Description],"") | I9: =IF(Table2[[#This Row],[Quantity]]<=Table2[[#This Row],[Reorder Levels]],Table2[Item Description],"") -> Ben. App. Forms SF/001
A10: =SFMaterialNo -> 100220 | B10: =IF(A10="","",VLOOKUP(A10,SF.STOREPRIMARY[],2,FALSE)) -> Payment of Benefit Forms/004 | C10: =IF(A10="","",VLOOKUP(A10,'STOCK CONTROL SHEET'!Details,3,FALSE)) -> PCS | D10: =SF.STOREPRIMARY[Reorder Levels] -> 7500 | E10: =SF.STOREPRIMARY[Physical Stock Bal.] | G10: =SFMaterialNo -> 100220 | H10: =IF(Table2[[#This Row],[Quantity]]>Table2[[#This Row],[Reorder Levels]],Table2[Item Description],"") -> Payment of Benefit Forms/004 | I10: =IF(Table2[[#This Row],[Quantity]]<=Table2[[#This Row],[Reorder Levels]],Table2[Item Description],"")
A11: =SFMaterialNo -> 100210 | B11: =IF(A11="","",VLOOKUP(A11,SF.STOREPRIMARY[],2,FALSE)) -> Claim Confirmation SF/D/005 | C11: =IF(A11="","",VLOOKUP(A11,'STOCK CONTROL SHEET'!Details,3,FALSE)) -> PCS | D11: =SF.STOREPRIMARY[Reorder Levels] -> 7500 | E11: =SF.STOREPRIMARY[Physical Stock Bal.] -> 0 | G11: =SFMaterialNo -> 100210 | H11: =IF(Table2[[#This Row],[Quantity]]>Table2[[#This Row],[Reorder Levels]],Table2[Item Description],"") | I11: =IF(Table2[[#This Row],[Quantity]]<=Table2[[#This Row],[Reorder Levels]],Table2[Item Description],"") -> Claim Confirmation SF/D/005
A12: =SFMaterialNo -> 100162 | B12: =IF(A12="","",VLOOKUP(A12,SF.STOREPRIMARY[],2,FALSE)) -> Confidential Folders Pink | C12: =IF(A12="","",VLOOKUP(A12,'STOCK CONTROL SHEET'!Details,3,FALSE)) -> PCS | D12: =SF.STOREPRIMARY[Reorder Levels] -> 250 | E12: =SF.STOREPRIMARY[Physical Stock Bal.] -> 5 | G12: =SFMaterialNo -> 100162 | H12: =IF(Table2[[#This Row],[Quantity]]>Table2[[#This Row],[Reorder Levels]],Table2[Item Description],"") | I12: =IF(Table2[[#This Row],[Quantity]]<=Table2[[#This Row],[Reorder Levels]],Table2[Item Description],"") -> Confidential Folders Pink
A13: =SFMaterialNo -> 100144 | B13: =IF(A13="","",VLOOKUP(A13,SF.STOREPRIMARY[],2,FALSE)) -> Dummy B Certificate | C13: =IF(A13="","",VLOOKUP(A13,'STOCK CONTROL SHEET'!Details,3,FALSE)) -> PCS | D13: =SF.STOREPRIMARY[Reorder Levels] -> 100 | E13: =SF.STOREPRIMARY[Physical Stock Bal.] -> 201 | G13: =SFMaterialNo -> 100144 | H13: =IF(Table2[[#This Row],[Quantity]]>Table2[[#This Row],[Reorder Levels]],Table2[Item Description],"") -> Dummy B Certificate | I13: =IF(Table2[[#This Row],[Quantity]]<=Table2[[#This Row],[Reorder Levels]],Table2[Item Description],"")
A14: =SFMaterialNo -> 100125 | B14: =IF(A14="","",VLOOKUP(A14,SF.STOREPRIMARY[],2,FALSE)) -> Empty Cartons | C14: =IF(A14="","",VLOOKUP(A14,'STOCK CONTROL SHEET'!Details,3,FALSE)) -> NO | D14: =SF.STOREPRIMARY[Reorder Levels] -> 100 | E14: =SF.STOREPRIMARY[Physical Stock Bal.] -> 367 | G14: =SFMaterialNo -> 100125 | H14: =IF(Table2[[#This Row],[Quantity]]>Table2[[#This Row],[Reorder Levels]],Table2[Item Description],"") -> Empty Cartons | I14: =IF(Table2[[#This Row],[Quantity]]<=Table2[[#This Row],[Reorder Levels]],Table2[Item Description],"")
A15: =SFMaterialNo -> 100123 | B15: =IF(A15="","",VLOOKUP(A15,SF.STOREPRIMARY[],2,FALSE)) -> Envelopes A4 | C15: =IF(A15="","",VLOOKUP(A15,'STOCK CONTROL SHEET'!Details,3,FALSE)) -> PCS | D15: =SF.STOREPRIMARY[Reorder Levels] -> 9000 | E15: =SF.STOREPRIMARY[Physical Stock Bal.] -> 12851 | G15: =SFMaterialNo -> 100123 | H15: =IF(Table2[[#This Row],[Quantity]]>Table2[[#This Row],[Reorder Levels]],Table2[Item Description],"") -> Envelopes A4 | I15: =IF(Table2[[#This Row],[Quantity]]<=Table2[[#This Row],[Reorder Levels]],Table2[Item Description],"")
A16: =SFMaterialNo -> 100228 | B16: =IF(A16="","",VLOOKUP(A16,SF.STOREPRIMARY[],2,FALSE)) -> A3 Security Envelopes | C16: =IF(A16="","",VLOOKUP(A16,'STOCK CONTROL SHEET'!Details,3,FALSE)) -> PCS | D16: =SF.STOREPRIMARY[Reorder Levels] -> 600 | E16: =SF.STOREPRIMARY[Physical Stock Bal.] -> 0 | G16: =SFMaterialNo -> 100228 | H16: =IF(Table2[[#This Row],[Quantity]]>Table2[[#This Row],[Reorder Levels]],Table2[Item Description],"") | I16: =IF(Table2[[#This Row],[Quantity]]<=Table2[[#This Row],[Reorder Levels]],Table2[Item Description],"") -> A3 Security Envelopes
... A38: =SFMaterialNo -> 100127 | B38: =IF(A38="","",VLOOKUP(A38,SF.STOREPRIMARY[],2,FALSE)) -> Withdrawal Ben. Folders | C38: =IF(A38="","",VLOOKUP(A38,'STOCK CONTROL SHEET'!Details,3,FALSE)) -> PCS | D38: =SF.STOREPRIMARY[Reorder Levels] -> 5000 | E38: =SF.STOREPRIMARY[Physical Stock Bal.] -> 750 | G38: =SFMaterialNo -> 100127 | H38: =IF(Table2[[#This Row],[Quantity]]>Table2[[#This Row],[Reorder Levels]],Table2[Item Description],"") | I38: =IF(Table2[[#This Row],[Quantity]]<=Table2[[#This Row],[Reorder Levels]],Table2[Item Description],"") -> Withdrawal Ben. Folders
A39: =COMPMaterialNo -> 100172 | B39: =IF(A39="","",VLOOKUP(A39,COMP.STOREPRIMARY,2,FALSE)) -> 1 Part Statement Paper | C39: =IF(A39="","",VLOOKUP(A39,'STOCK CONTROL SHEET'!Details,3,FALSE)) -> PCS | D39: =COMP.STOREReorderLevels -> 150000 | E39: =COMP.STOREPhysicalBal. -> 235000 | F39: COMPUTER STORE | G39: =COMPMaterialNo -> 100172 | H39: =IF(Table2[[#This Row],[Quantity]]>Table2[[#This Row],[Reorder Levels]],Table2[Item Description],"") -> 1 Part Statement Paper | I39: =IF(Table2[[#This Row],[Quantity]]<=Table2[[#This Row],[Reorder Levels]],Table2[Item Description],"")
A40: =COMPMaterialNo -> 41 | B40: =IF(A40="","",VLOOKUP(A40,COMP.STOREPRIMARY,2,FALSE)) -> Tonner Kit TK-8525 (Magenta) | C40: =IF(A40="","",VLOOKUP(A40,'STOCK CONTROL SHEET'!Details,3,FALSE)) -> NO | D40: =COMP.STOREReorderLevels -> 0 | E40: =COMP.STOREPhysicalBal. -> 0 | G40: =COMPMaterialNo -> 41 | H40: =IF(Table2[[#This Row],[Quantity]]>Table2[[#This Row],[Reorder Levels]],Table2[Item Description],"") | I40: =IF(Table2[[#This Row],[Quantity]]<=Table2[[#This Row],[Reorder Levels]],Table2[Item Description],"") -> Tonner Kit TK-8525 (Magenta)
A41: =COMPMaterialNo -> 0 | B41: =IF(A41="","",VLOOKUP(A41,COMP.STOREPRIMARY,2,FALSE)) -> #N/A | C41: =IF(A41="","",VLOOKUP(A41,'STOCK CONTROL SHEET'!Details,3,FALSE)) -> #N/A | D41: =COMP.STOREReorderLevels -> 0 | E41: =COMP.STOREPhysicalBal. -> 3 | G41: =COMPMaterialNo -> 0 | H41: =IF(Table2[[#This Row],[Quantity]]>Table2[[#This Row],[Reorder Levels]],Table2[Item Description],"") -> #N/A | I41: =IF(Table2[[#This Row],[Quantity]]<=Table2[[#This Row],[Reorder Levels]],Table2[Item Description],"")
A42: =COMPMaterialNo -> 0 | B42: =IF(A42="","",VLOOKUP(A42,COMP.STOREPRIMARY,2,FALSE)) -> #N/A | C42: =IF(A42="","",VLOOKUP(A42,'STOCK CONTROL SHEET'!Details,3,FALSE)) -> #N/A | D42: =COMP.STOREReorderLevels -> 0 | E42: =COMP.STOREPhysicalBal. -> 1 | G42: =COMPMaterialNo -> 0 | H42: =IF(Table2[[#This Row],[Quantity]]>Table2[[#This Row],[Reorder Levels]],Table2[Item Description],"") -> #N/A | I42: =IF(Table2[[#This Row],[Quantity]]<=Table2[[#This Row],[Reorder Levels]],Table2[Item Description],"")
A43: =COMPMaterialNo -> 0 | B43: =IF(A43="","",VLOOKUP(A43,COMP.STOREPRIMARY,2,FALSE)) -> #N/A | C43: =IF(A43="","",VLOOKUP(A43,'STOCK CONTROL SHEET'!Details,3,FALSE)) -> #N/A | D43: =COMP.STOREReorderLevels -> 0 | E43: =COMP.STOREPhysicalBal. -> 5 | G43: =COMPMaterialNo -> 0 | H43: =IF(Table2[[#This Row],[Quantity]]>Table2[[#This Row],[Reorder Levels]],Table2[Item Description],"") -> #N/A | I43: =IF(Table2[[#This Row],[Quantity]]<=Table2[[#This Row],[Reorder Levels]],Table2[Item Description],"")
A44: =COMPMaterialNo -> 0 | B44: =IF(A44="","",VLOOKUP(A44,COMP.STOREPRIMARY,2,FALSE)) -> #N/A | C44: =IF(A44="","",VLOOKUP(A44,'STOCK CONTROL SHEET'!Details,3,FALSE)) -> #N/A | D44: =COMP.STOREReorderLevels -> 0 | E44: =COMP.STOREPhysicalBal. -> 7 | G44: =COMPMaterialNo -> 0 | H44: =IF(Table2[[#This Row],[Quantity]]>Table2[[#This Row],[Reorder Levels]],Table2[Item Description],"") -> #N/A | I44: =IF(Table2[[#This Row],[Quantity]]<=Table2[[#This Row],[Reorder Levels]],Table2[Item Description],"")
A45: =COMPMaterialNo -> 0 | B45: =IF(A45="","",VLOOKUP(A45,COMP.STOREPRIMARY,2,FALSE)) -> #N/A | C45: =IF(A45="","",VLOOKUP(A45,'STOCK CONTROL SHEET'!Details,3,FALSE)) -> #N/A | D45: =COMP.STOREReorderLevels -> 0 | E45: =COMP.STOREPhysicalBal. -> 6 | G45: =COMPMaterialNo -> 0 | H45: =IF(Table2[[#This Row],[Quantity]]>Table2[[#This Row],[Reorder Levels]],Table2[Item Description],"") -> #N/A | I45: =IF(Table2[[#This Row],[Quantity]]<=Table2[[#This Row],[Reorder Levels]],Table2[Item Description],"")
A46: =COMPMaterialNo -> 100229 | B46: =IF(A46="","",VLOOKUP(A46,COMP.STOREPRIMARY,2,FALSE)) -> 2 PP NCR Carbonated | C46: =IF(A46="","",VLOOKUP(A46,'STOCK CONTROL SHEET'!Details,3,FALSE)) -> PCS | D46: =COMP.STOREReorderLevels -> 150000 | E46: =COMP.STOREPhysicalBal. -> 230000 | G46: =COMPMaterialNo -> 100229 | H46: =IF(Table2[[#This Row],[Quantity]]>Table2[[#This Row],[Reorder Levels]],Table2[Item Description],"") -> 2 PP NCR Carbonated | I46: =IF(Table2[[#This Row],[Quantity]]<=Table2[[#This Row],[Reorder Levels]],Table2[Item Description],"")
A47: =COMPMaterialNo -> 200033 | B47: =IF(A47="","",VLOOKUP(A47,COMP.STOREPRIMARY,2,FALSE)) -> Epson Ribbon 2180 | C47: =IF(A47="","",VLOOKUP(A47,'STOCK CONTROL SHEET'!Details,3,FALSE)) -> PCS | D47: =COMP.STOREReorderLevels -> 0 | E47: =COMP.STOREPhysicalBal. -> 53 | G47: =COMPMaterialNo -> 200033 | H47: =IF(Table2[[#This Row],[Quantity]]>Table2[[#This Row],[Reorder Levels]],Table2[Item Description],"") -> Epson Ribbon 2180 | I47: =IF(Table2[[#This Row],[Quantity]]<=Table2[[#This Row],[Reorder Levels]],Table2[Item Description],"")
A48: =COMPMaterialNo -> 37 | B48: =IF(A48="","",VLOOKUP(A48,COMP.STOREPRIMARY,2,FALSE)) -> Epson EB Projector/amp | C48: =IF(A48="","",VLOOKUP(A48,'STOCK CONTROL SHEET'!Details,3,FALSE)) -> NO | D48: =COMP.STOREReorderLevels -> 0 | E48: =COMP.STOREPhysicalBal. -> 0 | G48: =COMPMaterialNo -> 37 | H48: =IF(Table2[[#This Row],[Quantity]]>Table2[[#This Row],[Reorder Levels]],Table2[Item Description],"") | I48: =IF(Table2[[#This Row],[Quantity]]<=Table2[[#This Row],[Reorder Levels]],Table2[Item Description],"") -> Epson EB Projector/amp
A49: =COMPMaterialNo -> 200033 | B49: =IF(A49="","",VLOOKUP(A49,COMP.STOREPRIMARY,2,FALSE)) -> Epson Ribbon 2180 | C49: =IF(A49="","",VLOOKUP(A49,'STOCK CONTROL SHEET'!Details,3,FALSE)) -> PCS | D49: =COMP.STOREReorderLevels -> 0 | E49: =COMP.STOREPhysicalBal. -> 11 | G49: =COMPMaterialNo -> 200033 | H49: =IF(Table2[[#This Row],[Quantity]]>Table2[[#This Row],[Reorder Levels]],Table2[Item Description],"") -> Epson Ribbon 2180 | I49: =IF(Table2[[#This Row],[Quantity]]<=Table2[[#This Row],[Reorder Levels]],Table2[Item Description],"")
A50: =COMPMaterialNo -> 0 | B50: =IF(A50="","",VLOOKUP(A50,COMP.STOREPRIMARY,2,FALSE)) -> #N/A | C50: =IF(A50="","",VLOOKUP(A50,'STOCK CONTROL SHEET'!Details,3,FALSE)) -> #N/A | D50: =COMP.STOREReorderLevels -> 0 | E50: =COMP.STOREPhysicalBal. -> 9 | G50: =COMPMaterialNo -> 0 | H50: =IF(Table2[[#This Row],[Quantity]]>Table2[[#This Row],[Reorder Levels]],Table2[Item Description],"") -> #N/A | I50: =IF(Table2[[#This Row],[Quantity]]<=Table2[[#This Row],[Reorder Levels]],Table2[Item Description],"")
A51: =COMPMaterialNo -> 0 | B51: =IF(A51="","",VLOOKUP(A51,COMP.STOREPRIMARY,2,FALSE)) -> #N/A | C51: =IF(A51="","",VLOOKUP(A51,'STOCK CONTROL SHEET'!Details,3,FALSE)) -> #N/A | D51: =COMP.STOREReorderLevels -> 0 | E51: =COMP.STOREPhysicalBal. -> 6 | G51: =COMPMaterialNo -> 0 | H51: =IF(Table2[[#This Row],[Quantity]]>Table2[[#This Row],[Reorder Levels]],Table2[Item Description],"") -> #N/A | I51: =IF(Table2[[#This Row],[Quantity]]<=Table2[[#This Row],[Reorder Levels]],Table2[Item Description],"")
... A124: =COMPMaterialNo -> 200017 | B124: =IF(A124="","",VLOOKUP(A124,COMP.STOREPRIMARY,2,FALSE)) -> Lex Mark C920 Ribbon Magenta | C124: =IF(A124="","",VLOOKUP(A124,'STOCK CONTROL SHEET'!Details,3,FALSE)) -> NO | D124: =COMP.STOREReorderLevels -> 1 | E124: =COMP.STOREPhysicalBal. -> 7 | G124: =COMPMaterialNo -> 200017 | H124: =IF(Table2[[#This Row],[Quantity]]>Table2[[#This Row],[Reorder Levels]],Table2[Item Description],"") -> Lex Mark C920 Ribbon Magenta | I124: =IF(Table2[[#This Row],[Quantity]]<=Table2[[#This Row],[Reorder Levels]],Table2[Item Description],"")
A125: =MAINTMaterialNo -> 282022 | B125: =IF(A125="","",VLOOKUP(A125,MAINT.STOREPRIMARY,2,FALSE)) -> Air Freshener | C125: =IF(A125="","",VLOOKUP(A125,'STOCK CONTROL SHEET'!Details,3,FALSE)) -> NO | D125: =MAINT.STOREReorderLevels -> 0 | E125: =MAINT.STOREPhysicalStockBal. -> 34 | F125: MAINTENANCE STORE | G125: =MAINTMaterialNo -> 282022 | H125: =IF(Table2[[#This Row],[Quantity]]>Table2[[#This Row],[Reorder Levels]],Table2[Item Description],"") -> Air Freshener | I125: =IF(Table2[[#This Row],[Quantity]]<=Table2[[#This Row],[Reorder Levels]],Table2[Item Description],"")
A126: =MAINTMaterialNo -> 282018 | B126: =IF(A126="","",VLOOKUP(A126,MAINT.STOREPRIMARY,2,FALSE)) -> Bar Soaps | C126: =IF(A126="","",VLOOKUP(A126,'STOCK CONTROL SHEET'!Details,3,FALSE)) -> PCS | D126: =MAINT.STOREReorderLevels -> 0 | E126: =MAINT.STOREPhysicalStockBal. -> 336 | G126: =MAINTMaterialNo -> 282018 | H126: =IF(Table2[[#This Row],[Quantity]]>Table2[[#This Row],[Reorder Levels]],Table2[Item Description],"") -> Bar Soaps | I126: =IF(Table2[[#This Row],[Quantity]]<=Table2[[#This Row],[Reorder Levels]],Table2[Item Description],"")
A127: =MAINTMaterialNo -> 252014 | B127: =IF(A127="","",VLOOKUP(A127,MAINT.STOREPRIMARY,2,FALSE)) -> 4-Way Extension Socket | C127: =IF(A127="","",VLOOKUP(A127,'STOCK CONTROL SHEET'!Details,3,FALSE)) -> NO | D127: =MAINT.STOREReorderLevels -> 6 | E127: =MAINT.STOREPhysicalStockBal. -> 23 | G127: =MAINTMaterialNo -> 252014 | H127: =IF(Table2[[#This Row],[Quantity]]>Table2[[#This Row],[Reorder Levels]],Table2[Item Description],"") -> 4-Way Extension Socket | I127: =IF(Table2[[#This Row],[Quantity]]<=Table2[[#This Row],[Reorder Levels]],Table2[Item Description],"")
A128: =MAINTMaterialNo -> 252015 | B128: =IF(A128="","",VLOOKUP(A128,MAINT.STOREPRIMARY,2,FALSE)) -> Single Socket | C128: =IF(A128="","",VLOOKUP(A128,'STOCK CONTROL SHEET'!Details,3,FALSE)) -> NO | D128: =MAINT.STOREReorderLevels -> 0 | E128: =MAINT.STOREPhysicalStockBal. -> 24 | G128: =MAINTMaterialNo -> 252015 | H128: =IF(Table2[[#This Row],[Quantity]]>Table2[[#This Row],[Reorder Levels]],Table2[Item Description],"") -> Single Socket | I128: =IF(Table2[[#This Row],[Quantity]]<=Table2[[#This Row],[Reorder Levels]],Table2[Item Description],"")
A129: =MAINTMaterialNo -> 252018 | B129: =IF(A129="","",VLOOKUP(A129,MAINT.STOREPRIMARY,2,FALSE)) -> 13 Amps Top Plug | C129: =IF(A129="","",VLOOKUP(A129,'STOCK CONTROL SHEET'!Details,3,FALSE)) -> NO | D129: =MAINT.STOREReorderLevels -> 4 | E129: =MAINT.STOREPhysicalStockBal. -> 25 | G129: =MAINTMaterialNo -> 252018 | H129: =IF(Table2[[#This Row],[Quantity]]>Table2[[#This Row],[Reorder Levels]],Table2[Item Description],"") -> 13 Amps Top Plug | I129: =IF(Table2[[#This Row],[Quantity]]<=Table2[[#This Row],[Reorder Levels]],Table2[Item Description],"")
A130: =MAINTMaterialNo -> 100 | B130: =IF(A130="","",VLOOKUP(A130,MAINT.STOREPRIMARY,2,FALSE)) -> 40 Amp Tap of Unit | C130: =IF(A130="","",VLOOKUP(A130,'STOCK CONTROL SHEET'!Details,3,FALSE)) -> NO | D130: =MAINT.STOREReorderLevels -> 0 | E130: =MAINT.STOREPhysicalStockBal. -> 0 | G130: =MAINTMaterialNo -> 100 | H130: =IF(Table2[[#This Row],[Quantity]]>Table2[[#This Row],[Reorder Levels]],Table2[Item Description],"") | I130: =IF(Table2[[#This Row],[Quantity]]<=Table2[[#This Row],[Reorder Levels]],Table2[Item Description],"") -> 40 Amp Tap of Unit
A131: =MAINTMaterialNo -> 101 | B131: =IF(A131="","",VLOOKUP(A131,MAINT.STOREPRIMARY,2,FALSE)) -> Blower | C131: =IF(A131="","",VLOOKUP(A131,'STOCK CONTROL SHEET'!Details,3,FALSE)) -> NO | D131: =MAINT.STOREReorderLevels -> 0 | E131: =MAINT.STOREPhysicalStockBal. -> 1 | G131: =MAINTMaterialNo -> 101 | H131: =IF(Table2[[#This Row],[Quantity]]>Table2[[#This Row],[Reorder Levels]],Table2[Item Description],"") -> Blower | I131: =IF(Table2[[#This Row],[Quantity]]<=Table2[[#This Row],[Reorder Levels]],Table2[Item Description],"")
A132: =MAINTMaterialNo -> 252040 | B132: =IF(A132="","",VLOOKUP(A132,MAINT.STOREPRIMARY,2,FALSE)) -> Chokes 4/6/8 | C132: =IF(A132="","",VLOOKUP(A132,'STOCK CONTROL SHEET'!Details,3,FALSE)) -> NO | D132: =MAINT.STOREReorderLevels -> 0 | E132: =MAINT.STOREPhysicalStockBal. -> 50 | G132: =MAINTMaterialNo -> 252040 | H132: =IF(Table2[[#This Row],[Quantity]]>Table2[[#This Row],[Reorder Levels]],Table2[Item Description],"") -> Chokes 4/6/8 | I132: =IF(Table2[[#This Row],[Quantity]]<=Table2[[#This Row],[Reorder Levels]],Table2[Item Description],"")
A133: =MAINTMaterialNo -> 272002 | B133: =IF(A133="","",VLOOKUP(A133,MAINT.STOREPRIMARY,2,FALSE)) -> Disposable Gloves | C133: =IF(A133="","",VLOOKUP(A133,'STOCK CONTROL SHEET'!Details,3,FALSE)) -> PAIRS | D133: =MAINT.STOREReorderLevels -> 0 | E133: =MAINT.STOREPhysicalStockBal. -> 100 | G133: =MAINTMaterialNo -> 272002 | H133: =IF(Table2[[#This Row],[Quantity]]>Table2[[#This Row],[Reorder Levels]],Table2[Item Description],"") -> Disposable Gloves | I133: =IF(Table2[[#This Row],[Quantity]]<=Table2[[#This Row],[Reorder Levels]],Table2[Item Description],"")
...

Sheet STORE PERFORMANCE
A1: VALUE OF DEFICIENCIES & SURPLUS | G1: RESPECTIVE DAILY STORE PERFOMANCE
A2: SF STORE | G2: Store | H2: Value of Deficiency | I2: Value of Surplus | J2: Row Labels | K2: Sum of Value of Deficiency | L2: Sum of Value of Surplus
A3: Material No | B3: Item Description | C3: Unit of Issue | D3: Quantity Deficit | E3: Quantity Surplus | G3: SF | H3: =SUM(Table8[Quantity Deficit]) -> #VALUE! | I3: =SUM(Table8[Quantity Surplus]) -> #VALUE! | J3: Grand Total | K3: #DIV/0! | L3: #DIV/0!
A4: =SFMaterialNo -> 282014 | B4: =IF(A4="","",VLOOKUP(A4,'STOCK CONTROL SHEET'!Details,2,FALSE)) -> Tissue Papers | C4: =IF(A4="","",VLOOKUP(A4,'STOCK CONTROL SHEET'!Details,3,FALSE)) -> ROLL | D4: =INDEX(SF.STOREPRIMARY[],MATCH('STORE PERFORMANCE'!A4,SFMaterialNo,0),9) | E4: =INDEX(SF.STOREPRIMARY[],MATCH('STORE PERFORMANCE'!A4,SF.STOREPRIMARY[Material No],0),10) | G4: Computer | H4: =SUM(Table9[Quantity Deficit]) -> 36 | I4: =SUM(Table9[Quantity Surplus]) -> 342102
A5: =SFMaterialNo -> 100126 | B5: =IF(A5="","",VLOOKUP(A5,'STOCK CONTROL SHEET'!Details,2,FALSE)) -> Administration Folders | C5: =IF(A5="","",VLOOKUP(A5,'STOCK CONTROL SHEET'!Details,3,FALSE)) -> PCS | D5: =INDEX(SF.STOREPRIMARY[],MATCH('STORE PERFORMANCE'!A5,SFMaterialNo,0),9) -> 375 | E5: =INDEX(SF.STOREPRIMARY[],MATCH('STORE PERFORMANCE'!A5,SF.STOREPRIMARY[Material No],0),10) | G5: Maintenance | H5: =SUM(Table10[Quantity Deficit]) -> #VALUE! | I5: =SUM(Table10[Quantity Surplus]) -> #VALUE!
A6: =SFMaterialNo -> 100128 | B6: =IF(A6="","",VLOOKUP(A6,'STOCK CONTROL SHEET'!Details,2,FALSE)) -> Age Benefit Folders | C6: =IF(A6="","",VLOOKUP(A6,'STOCK CONTROL SHEET'!Details,3,FALSE)) -> PCS | D6: =INDEX(SF.STOREPRIMARY[],MATCH('STORE PERFORMANCE'!A6,SFMaterialNo,0),9) | E6: =INDEX(SF.STOREPRIMARY[],MATCH('STORE PERFORMANCE'!A6,SF.STOREPRIMARY[Material No],0),10) -> 76
A7: =SFMaterialNo -> 100216 | B7: =IF(A7="","",VLOOKUP(A7,'STOCK CONTROL SHEET'!Details,2,FALSE)) -> App. For Personal Exemption Forms | C7: =IF(A7="","",VLOOKUP(A7,'STOCK CONTROL SHEET'!Details,3,FALSE)) -> PCS | D7: =INDEX(SF.STOREPRIMARY[],MATCH('STORE PERFORMANCE'!A7,SFMaterialNo,0),9) | E7: =INDEX(SF.STOREPRIMARY[],MATCH('STORE PERFORMANCE'!A7,SF.STOREPRIMARY[Material No],0),10) | G7: Total | H7: =SUM(Table5[Value of Deficiency]) -> #VALUE! | I7: =SUM(Table5[Value of Surplus]) -> #VALUE!
A8: =SFMaterialNo -> 100139 | B8: =IF(A8="","",VLOOKUP(A8,'STOCK CONTROL SHEET'!Details,2,FALSE)) -> App. For Employer SF/001 | C8: =IF(A8="","",VLOOKUP(A8,'STOCK CONTROL SHEET'!Details,3,FALSE)) -> PCS | D8: =INDEX(SF.STOREPRIMARY[],MATCH('STORE PERFORMANCE'!A8,SFMaterialNo,0),9) -> 2750 | E8: =INDEX(SF.STOREPRIMARY[],MATCH('STORE PERFORMANCE'!A8,SF.STOREPRIMARY[Material No],0),10)
A9: =SFMaterialNo -> 100218 | B9: =IF(A9="","",VLOOKUP(A9,'STOCK CONTROL SHEET'!Details,2,FALSE)) -> Ben. App. Forms SF/001 | C9: =IF(A9="","",VLOOKUP(A9,'STOCK CONTROL SHEET'!Details,3,FALSE)) -> PCS | D9: =INDEX(SF.STOREPRIMARY[],MATCH('STORE PERFORMANCE'!A9,SFMaterialNo,0),9) -> 3800 | E9: =INDEX(SF.STOREPRIMARY[],MATCH('STORE PERFORMANCE'!A9,SF.STOREPRIMARY[Material No],0),10)
A10: =SFMaterialNo -> 100220 | B10: =IF(A10="","",VLOOKUP(A10,'STOCK CONTROL SHEET'!Details,2,FALSE)) -> Payment of Benefit Forms/004 | C10: =IF(A10="","",VLOOKUP(A10,'STOCK CONTROL SHEET'!Details,3,FALSE)) -> PCS | D10: =INDEX(SF.STOREPRIMARY[],MATCH('STORE PERFORMANCE'!A10,SFMaterialNo,0),9) -> #VALUE! | E10: =INDEX(SF.STOREPRIMARY[],MATCH('STORE PERFORMANCE'!A10,SF.STOREPRIMARY[Material No],0),10) -> #VALUE!
A11: =SFMaterialNo -> 100210 | B11: =IF(A11="","",VLOOKUP(A11,'STOCK CONTROL SHEET'!Details,2,FALSE)) -> Claim Confirmation SF/D/005 | C11: =IF(A11="","",VLOOKUP(A11,'STOCK CONTROL SHEET'!Details,3,FALSE)) -> PCS | D11: =INDEX(SF.STOREPRIMARY[],MATCH('STORE PERFORMANCE'!A11,SFMaterialNo,0),9) | E11: =INDEX(SF.STOREPRIMARY[],MATCH('STORE PERFORMANCE'!A11,SF.STOREPRIMARY[Material No],0),10)
A12: =SFMaterialNo -> 100162 | B12: =IF(A12="","",VLOOKUP(A12,'STOCK CONTROL SHEET'!Details,2,FALSE)) -> Confidential Folders Pink | C12: =IF(A12="","",VLOOKUP(A12,'STOCK CONTROL SHEET'!Details,3,FALSE)) -> PCS | D12: =INDEX(SF.STOREPRIMARY[],MATCH('STORE PERFORMANCE'!A12,SFMaterialNo,0),9) -> 165 | E12: =INDEX(SF.STOREPRIMARY[],MATCH('STORE PERFORMANCE'!A12,SF.STOREPRIMARY[Material No],0),10)
A13: =SFMaterialNo -> 100144 | B13: =IF(A13="","",VLOOKUP(A13,'STOCK CONTROL SHEET'!Details,2,FALSE)) -> Dummy B Certificate | C13: =IF(A13="","",VLOOKUP(A13,'STOCK CONTROL SHEET'!Details,3,FALSE)) -> PCS | D13: =INDEX(SF.STOREPRIMARY[],MATCH('STORE PERFORMANCE'!A13,SFMaterialNo,0),9) | E13: =INDEX(SF.STOREPRIMARY[],MATCH('STORE PERFORMANCE'!A13,SF.STOREPRIMARY[Material No],0),10)
A14: =SFMaterialNo -> 100125 | B14: =IF(A14="","",VLOOKUP(A14,'STOCK CONTROL SHEET'!Details,2,FALSE)) -> Empty Cartons | C14: =IF(A14="","",VLOOKUP(A14,'STOCK CONTROL SHEET'!Details,3,FALSE)) -> NO | D14: =INDEX(SF.STOREPRIMARY[],MATCH('STORE PERFORMANCE'!A14,SFMaterialNo,0),9) -> 130 | E14: =INDEX(SF.STOREPRIMARY[],MATCH('STORE PERFORMANCE'!A14,SF.STOREPRIMARY[Material No],0),10)
A15: =SFMaterialNo -> 100123 | B15: =IF(A15="","",VLOOKUP(A15,'STOCK CONTROL SHEET'!Details,2,FALSE)) -> Envelopes A4 | C15: =IF(A15="","",VLOOKUP(A15,'STOCK CONTROL SHEET'!Details,3,FALSE)) -> PCS | D15: =INDEX(SF.STOREPRIMARY[],MATCH('STORE PERFORMANCE'!A15,SFMaterialNo,0),9) | E15: =INDEX(SF.STOREPRIMARY[],MATCH('STORE PERFORMANCE'!A15,SF.STOREPRIMARY[Material No],0),10) -> 3206
A16: =SFMaterialNo -> 100228 | B16: =IF(A16="","",VLOOKUP(A16,'STOCK CONTROL SHEET'!Details,2,FALSE)) -> A3 Security Envelopes | C16: =IF(A16="","",VLOOKUP(A16,'STOCK CONTROL SHEET'!Details,3,FALSE)) -> PCS | D16: =INDEX(SF.STOREPRIMARY[],MATCH('STORE PERFORMANCE'!A16,SFMaterialNo,0),9) -> 10 | E16: =INDEX(SF.STOREPRIMARY[],MATCH('STORE PERFORMANCE'!A16,SF.STOREPRIMARY[Material No],0),10)
A17: =SFMaterialNo -> 100124 | B17: =IF(A17="","",VLOOKUP(A17,'STOCK CONTROL SHEET'!Details,2,FALSE)) -> Envelopes A3 (16*12) White | C17: =IF(A17="","",VLOOKUP(A17,'STOCK CONTROL SHEET'!Details,3,FALSE)) -> PCS | D17: =INDEX(SF.STOREPRIMARY[],MATCH('STORE PERFORMANCE'!A17,SFMaterialNo,0),9) | E17: =INDEX(SF.STOREPRIMARY[],MATCH('STORE PERFORMANCE'!A17,SF.STOREPRIMARY[Material No],0),10) -> 25
A18: =SFMaterialNo -> 100122 | B18: =IF(A18="","",VLOOKUP(A18,'STOCK CONTROL SHEET'!Details,2,FALSE)) -> Envelopes A5 | C18: =IF(A18="","",VLOOKUP(A18,'STOCK CONTROL SHEET'!Details,3,FALSE)) -> PCS | D18: =INDEX(SF.STOREPRIMARY[],MATCH('STORE PERFORMANCE'!A18,SFMaterialNo,0),9) -> 3579 | E18: =INDEX(SF.STOREPRIMARY[],MATCH('STORE PERFORMANCE'!A18,SF.STOREPRIMARY[Material No],0),10)
A19: =SFMaterialNo -> 100130 | B19: =IF(A19="","",VLOOKUP(A19,'STOCK CONTROL SHEET'!Details,2,FALSE)) -> Emigration Benefit Folders | C19: =IF(A19="","",VLOOKUP(A19,'STOCK CONTROL SHEET'!Details,3,FALSE)) -> PCS | D19: =INDEX(SF.STOREPRIMARY[],MATCH('STORE PERFORMANCE'!A19,SFMaterialNo,0),9) | E19: =INDEX(SF.STOREPRIMARY[],MATCH('STORE PERFORMANCE'!A19,SF.STOREPRIMARY[Material No],0),10) -> 288
... A38: =SFMaterialNo -> 100127 | B38: =IF(A38="","",VLOOKUP(A38,'STOCK CONTROL SHEET'!Details,2,FALSE)) -> Withdrawal Ben. Folders | C38: =IF(A38="","",VLOOKUP(A38,'STOCK CONTROL SHEET'!Details,3,FALSE)) -> PCS | D38: =INDEX(SF.STOREPRIMARY[],MATCH('STORE PERFORMANCE'!A38,SFMaterialNo,0),9) -> 390 | E38: =INDEX(SF.STOREPRIMARY[],MATCH('STORE PERFORMANCE'!A38,SF.STOREPRIMARY[Material No],0),10)
A39: COMPUTER STORE
A40: Material No | B40: Item Description | C40: Unit of Issue | D40: Quantity Deficit | E40: Quantity Surplus
A41: 100172 | B41: =IF(A41="","",VLOOKUP(A41,'STOCK CONTROL SHEET'!Details,2,FALSE)) -> 1 Part Statement Paper | C41: =IF(A41="","",VLOOKUP(A41,'STOCK CONTROL SHEET'!Details,3,FALSE)) -> PCS | D41: =INDEX(COMP.STOREPRIMARY,MATCH('STORE PERFORMANCE'!A41,COMPMaterialNo,0),9) | E41: =INDEX(COMP.STOREPRIMARY,MATCH('STORE PERFORMANCE'!A41,COMPMaterialNo,0),10) -> 154000
A42: 100229 | B42: =IF(A42="","",VLOOKUP(A42,'STOCK CONTROL SHEET'!Details,2,FALSE)) -> 2 PP NCR Carbonated | C42: =IF(A42="","",VLOOKUP(A42,'STOCK CONTROL SHEET'!Details,3,FALSE)) -> PCS | D42: =INDEX(COMP.STOREPRIMARY,MATCH('STORE PERFORMANCE'!A42,COMPMaterialNo,0),9) | E42: =INDEX(COMP.STOREPRIMARY,MATCH('STORE PERFORMANCE'!A42,COMPMaterialNo,0),10) -> 178000
A43: 200033 | B43: =IF(A43="","",VLOOKUP(A43,'STOCK CONTROL SHEET'!Details,2,FALSE)) -> Epson Ribbon 2180 | C43: =IF(A43="","",VLOOKUP(A43,'STOCK CONTROL SHEET'!Details,3,FALSE)) -> PCS | D43: =INDEX(COMP.STOREPRIMARY,MATCH('STORE PERFORMANCE'!A43,COMPMaterialNo,0),9) | E43: =INDEX(COMP.STOREPRIMARY,MATCH('STORE PERFORMANCE'!A43,COMPMaterialNo,0),10) -> 2
A44: 37 | B44: =IF(A44="","",VLOOKUP(A44,'STOCK CONTROL SHEET'!Details,2,FALSE)) -> Epson EB Projector/amp | C44: =IF(A44="","",VLOOKUP(A44,'STOCK CONTROL SHEET'!Details,3,FALSE)) -> NO | D44: =INDEX(COMP.STOREPRIMARY,MATCH('STORE PERFORMANCE'!A44,COMPMaterialNo,0),9) | E44: =INDEX(COMP.STOREPRIMARY,MATCH('STORE PERFORMANCE'!A44,COMPMaterialNo,0),10)
A45: 200024 | B45: =IF(A45="","",VLOOKUP(A45,'STOCK CONTROL SHEET'!Details,2,FALSE)) -> Epson DFX 5000 Ribbon(8766) | C45: =IF(A45="","",VLOOKUP(A45,'STOCK CONTROL SHEET'!Details,3,FALSE)) -> PCS | D45: =INDEX(COMP.STOREPRIMARY,MATCH('STORE PERFORMANCE'!A45,COMPMaterialNo,0),9) | E45: =INDEX(COMP.STOREPRIMARY,MATCH('STORE PERFORMANCE'!A45,COMPMaterialNo,0),10) -> 7
A46: 200031 | B46: =IF(A46="","",VLOOKUP(A46,'STOCK CONTROL SHEET'!Details,2,FALSE)) -> Epson Ribbon LX 300 (8750) | C46: =IF(A46="","",VLOOKUP(A46,'STOCK CONTROL SHEET'!Details,3,FALSE)) -> NO | D46: =INDEX(COMP.STOREPRIMARY,MATCH('STORE PERFORMANCE'!A46,COMPMaterialNo,0),9) | E46: =INDEX(COMP.STOREPRIMARY,MATCH('STORE PERFORMANCE'!A46,COMPMaterialNo,0),10) -> 5
A47: 200030 | B47: =IF(A47="","",VLOOKUP(A47,'STOCK CONTROL SHEET'!Details,2,FALSE)) -> Epson DFX 9000 | C47: =IF(A47="","",VLOOKUP(A47,'STOCK CONTROL SHEET'!Details,3,FALSE)) -> NO | D47: =INDEX(COMP.STOREPRIMARY,MATCH('STORE PERFORMANCE'!A47,COMPMaterialNo,0),9) | E47: =INDEX(COMP.STOREPRIMARY,MATCH('STORE PERFORMANCE'!A47,COMPMaterialNo,0),10) -> 8
A48: 200067 | B48: =IF(A48="","",VLOOKUP(A48,'STOCK CONTROL SHEET'!Details,2,FALSE)) -> Epson Ribbon LQ 690 (Black) | C48: =IF(A48="","",VLOOKUP(A48,'STOCK CONTROL SHEET'!Details,3,FALSE)) -> NO | D48: =INDEX(COMP.STOREPRIMARY,MATCH('STORE PERFORMANCE'!A48,COMPMaterialNo,0),9) -> 23 | E48: =INDEX(COMP.STOREPRIMARY,MATCH('STORE PERFORMANCE'!A48,COMPMaterialNo,0),10)
A49: 200034 | B49: =IF(A49="","",VLOOKUP(A49,'STOCK CONTROL SHEET'!Details,2,FALSE)) -> Epson Ribbon LX 2090 FX | C49: =IF(A49="","",VLOOKUP(A49,'STOCK CONTROL SHEET'!Details,3,FALSE)) -> NO | D49: =INDEX(COMP.STOREPRIMARY,MATCH('STORE PERFORMANCE'!A49,COMPMaterialNo,0),9) | E49: =INDEX(COMP.STOREPRIMARY,MATCH('STORE PERFORMANCE'!A49,COMPMaterialNo,0),10)
A50: 200070 | B50: =IF(A50="","",VLOOKUP(A50,'STOCK CONTROL SHEET'!Details,2,FALSE)) -> HP Laserjet Tonner 237A Black | C50: =IF(A50="","",VLOOKUP(A50,'STOCK CONTROL SHEET'!Details,3,FALSE)) -> NO | D50: =INDEX(COMP.STOREPRIMARY,MATCH('STORE PERFORMANCE'!A50,COMPMaterialNo,0),9) | E50: =INDEX(COMP.STOREPRIMARY,MATCH('STORE PERFORMANCE'!A50,COMPMaterialNo,0),10) -> 14
A51: 200066 | B51: =IF(A51="","",VLOOKUP(A51,'STOCK CONTROL SHEET'!Details,2,FALSE)) -> HP Laserjet Tonner 130A (Magenta) | C51: =IF(A51="","",VLOOKUP(A51,'STOCK CONTROL SHEET'!Details,3,FALSE)) -> NO | D51: =INDEX(COMP.STOREPRIMARY,MATCH('STORE PERFORMANCE'!A51,COMPMaterialNo,0),9) | E51: =INDEX(COMP.STOREPRIMARY,MATCH('STORE PERFORMANCE'!A51,COMPMaterialNo,0),10)
A52: 200007 | B52: =IF(A52="","",VLOOKUP(A52,'STOCK CONTROL SHEET'!Details,2,FALSE)) -> HP Laserjet 4600N Tonner (9723A) (Magenta) | C52: =IF(A52="","",VLOOKUP(A52,'STOCK CONTROL SHEET'!Details,3,FALSE)) -> NO | D52: =INDEX(COMP.STOREPRIMARY,MATCH('STORE PERFORMANCE'!A52,COMPMaterialNo,0),9) | E52: =INDEX(COMP.STOREPRIMARY,MATCH('STORE PERFORMANCE'!A52,COMPMaterialNo,0),10)
... A103: 41 | B103: =IF(A103="","",VLOOKUP(A103,'STOCK CONTROL SHEET'!Details,2,FALSE)) -> Tonner Kit TK-8525 (Magenta) | C103: =IF(A103="","",VLOOKUP(A103,'STOCK CONTROL SHEET'!Details,3,FALSE)) -> NO | D103: =INDEX(COMP.STOREPRIMARY,MATCH('STORE PERFORMANCE'!A103,COMPMaterialNo,0),9) | E103: =INDEX(COMP.STOREPRIMARY,MATCH('STORE PERFORMANCE'!A103,COMPMaterialNo,0),10)
A104: MAINTENANCE STORE
A105: Material No | B105: Item Description | C105: Unit of Issue | D105: Quantity Deficit | E105: Quantity Surplus
A106: 282022 | B106: =IF(A106="","",VLOOKUP(A106,'STOCK CONTROL SHEET'!Details,2,FALSE)) -> Air Freshener | C106: =IF(A106="","",VLOOKUP(A106,'STOCK CONTROL SHEET'!Details,3,FALSE)) -> NO | D106: =INDEX(MAINT.STOREPRIMARY,MATCH('STORE PERFORMANCE'!A106,MAINTMaterialNo,0),9) -> 14 | E106: =INDEX(MAINT.STOREPRIMARY,MATCH('STORE PERFORMANCE'!A106,MAINTMaterialNo,0),10)
A107: 282018 | B107: =IF(A107="","",VLOOKUP(A107,'STOCK CONTROL SHEET'!Details,2,FALSE)) -> Bar Soaps | C107: =IF(A107="","",VLOOKUP(A107,'STOCK CONTROL SHEET'!Details,3,FALSE)) -> PCS | D107: =INDEX(MAINT.STOREPRIMARY,MATCH('STORE PERFORMANCE'!A107,MAINTMaterialNo,0),9) | E107: =INDEX(MAINT.STOREPRIMARY,MATCH('STORE PERFORMANCE'!A107,MAINTMaterialNo,0),10) -> 25
A108: 252014 | B108: =IF(A108="","",VLOOKUP(A108,'STOCK CONTROL SHEET'!Details,2,FALSE)) -> 4-Way Extension Socket | C108: =IF(A108="","",VLOOKUP(A108,'STOCK CONTROL SHEET'!Details,3,FALSE)) -> NO | D108: =INDEX(MAINT.STOREPRIMARY,MATCH('STORE PERFORMANCE'!A108,MAINTMaterialNo,0),9) -> 7 | E108: =INDEX(MAINT.STOREPRIMARY,MATCH('STORE PERFORMANCE'!A108,MAINTMaterialNo,0),10)
...

Sheet SF STORE
A1: INVENTORY IN&OUT SCHEDULE
A2: Date | B2: Document No | C2: Type | D2: Material No | E2: Item Description | F2: Unit of Issue | G2: In&Out Qty | H2: Department | I2: Running Balance
A3: 45842 | B3: 490002787 | C3: Issue | D3: 100143 | E3: =IF(D3="","",VLOOKUP(D3,'STOCK CONTROL SHEET'!Details,2,FALSE)) -> Laminating Pouches | F3: =IF(D3="","",VLOOKUP(D3,'STOCK CONTROL SHEET'!Details,3,FALSE)) -> PCS | G3: 100 | H3: KIAMBU | I3: =IF(UnitsTable[Type]="Receipt",(SUM(UnitsTable[[#This Row],[In&Out Qty]])),(SUM(-INOUTQTY))) -> -100
A4: 45842 | B4: 4900027277 | C4: Issue | D4: 100220 | E4: =IF(D4="","",VLOOKUP(D4,'STOCK CONTROL SHEET'!Details,2,FALSE)) -> Payment of Benefit Forms/004 | F4: =IF(D4="","",VLOOKUP(D4,'STOCK CONTROL SHEET'!Details,3,FALSE)) -> PCS | G4: 500 | H4: KAKAMEGA | I4: =IF(UnitsTable[Type]="Receipt",(SUM(UnitsTable[[#This Row],[In&Out Qty]])),(SUM(-INOUTQTY))) -> -500 | M4: Issue | N4: EA
A5: 45842 | B5: 4900027277 | C5: Issue | D5: 100139 | E5: =IF(D5="","",VLOOKUP(D5,'STOCK CONTROL SHEET'!Details,2,FALSE)) -> App. For Employer SF/001 | F5: =IF(D5="","",VLOOKUP(D5,'STOCK CONTROL SHEET'!Details,3,FALSE)) -> PCS | G5: 500 | H5: KAKAMEGA | I5: =IF(UnitsTable[Type]="Receipt",(SUM(UnitsTable[[#This Row],[In&Out Qty]])),(SUM(-INOUTQTY))) -> -500 | M5: Receipt | N5: NO
A6: 45842 | B6: 4900027277 | C6: Issue | D6: 100218 | E6: =IF(D6="","",VLOOKUP(D6,'STOCK CONTROL SHEET'!Details,2,FALSE)) -> Ben. App. Forms SF/001 | F6: =IF(D6="","",VLOOKUP(D6,'STOCK CONTROL SHEET'!Details,3,FALSE)) -> PCS | G6: 300 | H6: KAKAMEGA | I6: =IF(UnitsTable[Type]="Receipt",(SUM(UnitsTable[[#This Row],[In&Out Qty]])),(SUM(-INOUTQTY))) -> -300 | M6: Loaned | N6: PAC
A7: 45842 | B7: 4900027277 | C7: Issue | D7: 100138 | E7: =IF(D7="","",VLOOKUP(D7,'STOCK CONTROL SHEET'!Details,2,FALSE)) -> Fingerprint Forms SF/003 | F7: =IF(D7="","",VLOOKUP(D7,'STOCK CONTROL SHEET'!Details,3,FALSE)) -> PCS | G7: 500 | H7: KAKAMEGA | I7: =IF(UnitsTable[Type]="Receipt",(SUM(UnitsTable[[#This Row],[In&Out Qty]])),(SUM(-INOUTQTY))) -> -500 | N7: PCS
A8: 45842 | B8: 4900027277 | C8: Issue | D8: 100145 | E8: =IF(D8="","",VLOOKUP(D8,'STOCK CONTROL SHEET'!Details,2,FALSE)) -> Membership Cards (Blank) | F8: =IF(D8="","",VLOOKUP(D8,'STOCK CONTROL SHEET'!Details,3,FALSE)) -> PCS | G8: 3000 | H8: KAKAMEGA | I8: =IF(UnitsTable[Type]="Receipt",(SUM(UnitsTable[[#This Row],[In&Out Qty]])),(SUM(-INOUTQTY))) -> -3000 | N8: PKT
A9: 45842 | B9: 4900027277 | C9: Issue | D9: 100213 | E9: =IF(D9="","",VLOOKUP(D9,'STOCK CONTROL SHEET'!Details,2,FALSE)) -> Schedule of Contribution | F9: =IF(D9="","",VLOOKUP(D9,'STOCK CONTROL SHEET'!Details,3,FALSE)) -> PCS | G9: 1000 | H9: KAKAMEGA | I9: =IF(UnitsTable[Type]="Receipt",(SUM(UnitsTable[[#This Row],[In&Out Qty]])),(SUM(-INOUTQTY))) -> -1000 | N9: RM
A10: 45842 | B10: 4900027277 | C10: Issue | D10: 100211 | E10: =IF(D10="","",VLOOKUP(D10,'STOCK CONTROL SHEET'!Details,2,FALSE)) -> Survivor Ben. Form | F10: =IF(D10="","",VLOOKUP(D10,'STOCK CONTROL SHEET'!Details,3,FALSE)) -> PCS | G10: 100 | H10: KAKAMEGA | I10: =IF(UnitsTable[Type]="Receipt",(SUM(UnitsTable[[#This Row],[In&Out Qty]])),(SUM(-INOUTQTY))) -> -100 | N10: ROLL
A11: 45842 | B11: 4900027277 | C11: Issue | D11: 100220 | E11: =IF(D11="","",VLOOKUP(D11,'STOCK CONTROL SHEET'!Details,2,FALSE)) -> Payment of Benefit Forms/004 | F11: =IF(D11="","",VLOOKUP(D11,'STOCK CONTROL SHEET'!Details,3,FALSE)) -> PCS | G11: 500 | H11: KAKAMEGA | I11: =IF(UnitsTable[Type]="Receipt",(SUM(UnitsTable[[#This Row],[In&Out Qty]])),(SUM(-INOUTQTY))) -> -500 | N11: TUBE
A12: 45842 | B12: 4900027282 | C12: Issue | D12: 100218 | E12: =IF(D12="","",VLOOKUP(D12,'STOCK CONTROL SHEET'!Details,2,FALSE)) -> Ben. App. Forms SF/001 | F12: =IF(D12="","",VLOOKUP(D12,'STOCK CONTROL SHEET'!Details,3,FALSE)) -> PCS | G12: 500 | H12: ELDORET | I12: =IF(UnitsTable[Type]="Receipt",(SUM(UnitsTable[[#This Row],[In&Out Qty]])),(SUM(-INOUTQTY))) -> -500
A13: 45842 | B13: 4900027282 | C13: Issue | D13: 100138 | E13: =IF(D13="","",VLOOKUP(D13,'STOCK CONTROL SHEET'!Details,2,FALSE)) -> Fingerprint Forms SF/003 | F13: =IF(D13="","",VLOOKUP(D13,'STOCK CONTROL SHEET'!Details,3,FALSE)) -> PCS | G13: 500 | H13: ELDORET | I13: =IF(UnitsTable[Type]="Receipt",(SUM(UnitsTable[[#This Row],[In&Out Qty]])),(SUM(-INOUTQTY))) -> -500
A14: 45842 | B14: 4900027282 | C14: Issue | D14: 100211 | E14: =IF(D14="","",VLOOKUP(D14,'STOCK CONTROL SHEET'!Details,2,FALSE)) -> Survivor Ben. Form | F14: =IF(D14="","",VLOOKUP(D14,'STOCK CONTROL SHEET'!Details,3,FALSE)) -> PCS | G14: 200 | H14: ELDORET | I14: =IF(UnitsTable[Type]="Receipt",(SUM(UnitsTable[[#This Row],[In&Out Qty]])),(SUM(-INOUTQTY))) -> -200
A15: 45842 | B15: 4900027282 | C15: Issue | D15: 100143 | E15: =IF(D15="","",VLOOKUP(D15,'STOCK CONTROL SHEET'!Details,2,FALSE)) -> Laminating Pouches | F15: =IF(D15="","",VLOOKUP(D15,'STOCK CONTROL SHEET'!Details,3,FALSE)) -> PCS | G15: 2000 | H15: ELDORET | I15: =IF(UnitsTable[Type]="Receipt",(SUM(UnitsTable[[#This Row],[In&Out Qty]])),(SUM(-INOUTQTY))) -> -2000
A16: 45842 | B16: 4900027282 | C16: Issue | D16: 100181 | E16: =IF(D16="","",VLOOKUP(D16,'STOCK CONTROL SHEET'!Details,2,FALSE)) -> Registration Gen. Folders | F16: =IF(D16="","",VLOOKUP(D16,'STOCK CONTROL SHEET'!Details,3,FALSE)) -> PCS | G16: 300 | H16: ELDORET | I16: =IF(UnitsTable[Type]="Receipt",(SUM(UnitsTable[[#This Row],[In&Out Qty]])),(SUM(-INOUTQTY))) -> -300
A17: 45842 | B17: 4900027282 | C17: Issue | D17: 100145 | E17: =IF(D17="","",VLOOKUP(D17,'STOCK CONTROL SHEET'!Details,2,FALSE)) -> Membership Cards (Blank) | F17: =IF(D17="","",VLOOKUP(D17,'STOCK CONTROL SHEET'!Details,3,FALSE)) -> PCS | G17: 3000 | H17: ELDORET | I17: =IF(UnitsTable[Type]="Receipt",(SUM(UnitsTable[[#This Row],[In&Out Qty]])),(SUM(-INOUTQTY))) -> -3000
A18: 45842 | B18: 4900027285 | C18: Issue | D18: 100138 | E18: =IF(D18="","",VLOOKUP(D18,'STOCK CONTROL SHEET'!Details,2,FALSE)) -> Fingerprint Forms SF/003 | F18: =IF(D18="","",VLOOKUP(D18,'STOCK CONTROL SHEET'!Details,3,FALSE)) -> PCS | G18: 500 | H18: KIAMBU | I18: =IF(UnitsTable[Type]="Receipt",(SUM(UnitsTable[[#This Row],[In&Out Qty]])),(SUM(-INOUTQTY))) -> -500
A19: 45842 | B19: 4900027285 | C19: Issue | D19: 100220 | E19: =IF(D19="","",VLOOKUP(D19,'STOCK CONTROL SHEET'!Details,2,FALSE)) -> Payment of Benefit Forms/004 | F19: =IF(D19="","",VLOOKUP(D19,'STOCK CONTROL SHEET'!Details,3,FALSE)) -> PCS | G19: 400 | H19: KIAMBU | I19: =IF(UnitsTable[Type]="Receipt",(SUM(UnitsTable[[#This Row],[In&Out Qty]])),(SUM(-INOUTQTY))) -> -400
A20: 45842 | B20: 4900027285 | C20: Issue | D20: 100139 | E20: =IF(D20="","",VLOOKUP(D20,'STOCK CONTROL SHEET'!Details,2,FALSE)) -> App. For Employer SF/001 | F20: =IF(D20="","",VLOOKUP(D20,'STOCK CONTROL SHEET'!Details,3,FALSE)) -> PCS | G20: 500 | H20: KIAMBU | I20: =IF(UnitsTable[Type]="Receipt",(SUM(UnitsTable[[#This Row],[In&Out Qty]])),(SUM(-INOUTQTY))) -> -500
A21: 45842 | B21: 4900027285 | C21: Issue | D21: 100181 | E21: =IF(D21="","",VLOOKUP(D21,'STOCK CONTROL SHEET'!Details,2,FALSE)) -> Registration Gen. Folders | F21: =IF(D21="","",VLOOKUP(D21,'STOCK CONTROL SHEET'!Details,3,FALSE)) -> PCS | G21: 200 | H21: KIAMBU | I21: =IF(UnitsTable[Type]="Receipt",(SUM(UnitsTable[[#This Row],[In&Out Qty]])),(SUM(-INOUTQTY))) -> -200
